<robot name="simple_car">

  <!-- ðŸ”¹ ì°¨ì²´ -->
  <link name="chassis">
    <inertial>
      <mass value="5"/>
      <inertia ixx="1" iyy="1" izz="1" ixy="0" ixz="0" iyz="0"/>
    </inertial>
    <visual>
      <geometry>
        <box size="1 0.5 0.2"/>
      </geometry>
      <origin xyz="0 0 0.3"/>
    </visual>
    <collision>
      <geometry>
        <box size="1 0.5 0.2"/>
      </geometry>
      <origin xyz="0 0 0.3"/>
    </collision>
  </link>

  <!-- ðŸ”¹ ì•žì™¼ìª½ ë°”í€´ -->
  <link name="wheel_fl">
    <inertial>
      <mass value="1"/>
      <inertia ixx="0.01" iyy="0.01" izz="0.01" ixy="0" ixz="0" iyz="0"/>
    </inertial>
    <visual>
      <geometry>
        <cylinder length="0.05" radius="0.1"/>
      </geometry>
      <origin xyz="0.5 0.3 0.1" rpy="1.57 0 0"/>
    </visual>
    <collision>
      <geometry>
        <cylinder length="0.05" radius="0.1"/>
      </geometry>
      <origin xyz="0.5 0.3 0.1" rpy="1.57 0 0"/>
    </collision>
  </link>

  <!-- ðŸ”¹ ì•žì˜¤ë¥¸ìª½ ë°”í€´ -->
  <link name="wheel_fr">
    <inertial>
      <mass value="1"/>
      <inertia ixx="0.01" iyy="0.01" izz="0.01" ixy="0" ixz="0" iyz="0"/>
    </inertial>
    <visual>
      <geometry>
        <cylinder length="0.05" radius="0.1"/>
      </geometry>
      <origin xyz="0.5 -0.3 0.1" rpy="1.57 0 0"/>
    </visual>
    <collision>
      <geometry>
        <cylinder length="0.05" radius="0.1"/>
      </geometry>
      <origin xyz="0.5 -0.3 0.1" rpy="1.57 0 0"/>
    </collision>
  </link>

  <!-- ðŸ”¹ ë’¤ì™¼ìª½ ë°”í€´ -->
  <link name="wheel_rl">
    <inertial>
      <mass value="1"/>
      <inertia ixx="0.01" iyy="0.01" izz="0.01" ixy="0" ixz="0" iyz="0"/>
    </inertial>
    <visual>
      <geometry>
        <cylinder length="0.05" radius="0.1"/>
      </geometry>
      <origin xyz="-0.5 0.3 0.1" rpy="1.57 0 0"/>
    </visual>
    <collision>
      <geometry>
        <cylinder length="0.05" radius="0.1"/>
      </geometry>
      <origin xyz="-0.5 0.3 0.1" rpy="1.57 0 0"/>
    </collision>
  </link>

  <!-- ðŸ”¹ ë’¤ì˜¤ë¥¸ìª½ ë°”í€´ -->
  <link name="wheel_rr">
    <inertial>
      <mass value="1"/>
      <inertia ixx="0.01" iyy="0.01" izz="0.01" ixy="0" ixz="0" iyz="0"/>
    </inertial>
    <visual>
      <geometry>
        <cylinder length="0.05" radius="0.1"/>
      </geometry>
      <origin xyz="-0.5 -0.3 0.1" rpy="1.57 0 0"/>
    </visual>
    <collision>
      <geometry>
        <cylinder length="0.05" radius="0.1"/>
      </geometry>
      <origin xyz="-0.5 -0.3 0.1" rpy="1.57 0 0"/>
    </collision>
  </link>

  <!-- ðŸ”¹ ì¡°ì¸íŠ¸ë“¤ -->
  <joint name="joint_fl" type="continuous">
    <parent link="chassis"/>
    <child link="wheel_fl"/>
    <origin xyz="0.5 0.3 0.1"/>
    <axis xyz="0 0 1"/>
    <limit effort="10" velocity="10"/>
  </joint>

  <joint name="joint_fr" type="continuous">
    <parent link="chassis"/>
    <child link="wheel_fr"/>
    <origin xyz="0.5 -0.3 0.1"/>
    <axis xyz="0 0 1"/>
    <limit effort="10" velocity="10"/>
  </joint>

  <joint name="joint_rl" type="continuous">
    <parent link="chassis"/>
    <child link="wheel_rl"/>
    <origin xyz="-0.5 0.3 0.1"/>
    <axis xyz="0 0 1"/>
    <limit effort="10" velocity="10"/>
  </joint>

  <joint name="joint_rr" type="continuous">
    <parent link="chassis"/>
    <child link="wheel_rr"/>
    <origin xyz="-0.5 -0.3 0.1"/>
    <axis xyz="0 0 1"/>
    <limit effort="10" velocity="10"/>
  </joint>

</robot>

